Workbook

Sheet Nodes
A1: Node_ID | B1: Latitude | C1: Longitude | D1: Location Name | E1: Country | F1: Domain | G1: Border | H1: node_prob
A2: 1 | B2: 52.39 | C2: 9.8 | D2: Hannover | E2: Germany | F2: 1 | G2: FALSE | H2: 1
A3: 2 | B3: 50.1 | C3: 8.67 | D3: Frankfurt | E3: Germany | F3: 1 | G3: TRUE | H3: 1
A4: 3 | B4: 53.55 | C4: 10.02 | D4: Hamburg | E4: Germany | F4: 1 | G4: FALSE | H4: 1
A5: 4 | B5: 53.6 | C5: 7.21 | D5: Norden | E5: Germany | F5: 1 | G5: FALSE | H5: 1
A6: 5 | B6: 53.08 | C6: 8.8 | D6: Bremen | E6: Germany | F6: 1 | G6: FALSE | H6: 1
A7: 6 | B7: 52.52 | C7: 13.4 | D7: Berlin | E7: Germany | F7: 1 | G7: FALSE | H7: 1
A8: 7 | B8: 48.13 | C8: 11.57 | D8: Munich | E8: Germany | F8: 1 | G8: TRUE | H8: 1
A9: 8 | B9: 48.4 | C9: 9.99 | D9: Ulm | E9: Germany | F9: 1 | G9: FALSE | H9: 1
A10: 9 | B10: 49.45 | C10: 11.08 | D10: Nuernberg | E10: Germany | F10: 1 | G10: FALSE | H10: 1
A11: 10 | B11: 48.73 | C11: 9.12 | D11: Stuttgart | E11: Germany | F11: 1 | G11: FALSE | H11: 1
A12: 11 | B12: 49.01 | C12: 8.41 | D12: Karlsruhe | E12: Germany | F12: 1 | G12: FALSE | H12: 1
A13: 12 | B13: 49.49 | C13: 8.49 | D13: Mannheim | E13: Germany | F13: 1 | G13: FALSE | H13: 1
A14: 13 | B14: 51.44 | C14: 7 | D14: Essen | E14: Germany | F14: 1 | G14: FALSE | H14: 1
A15: 14 | B15: 51.51 | C15: 7.48 | D15: Dortmund | E15: Germany | F15: 1 | G15: FALSE | H15: 1
A16: 15 | B16: 51.23 | C16: 6.78 | D16: Dusseldorf | E16: Germany | F16: 1 | G16: TRUE | H16: 1
A17: 16 | B17: 50.92 | C17: 7.01 | D17: Koeln | E17: Germany | F17: 1 | G17: FALSE | H17: 1
A18: 17 | B18: 51.34 | C18: 12.38 | D18: Leipzig | E18: Germany | F18: 1 | G18: FALSE | H18: 1
A19: 18 | B19: 50.95 | C19: 1.86 | D19: Calais | E19: France | F19: 2 | G19: TRUE | H19: 1
A20: 19 | B20: 47.9 | C20: 1.91 | D20: Orleans | E20: France | F20: 2 | G20: FALSE | H20: 1
A21: 20 | B21: 48.85 | C21: 2.35 | D21: Paris | E21: France | F21: 2 | G21: TRUE | H21: 1
A22: 21 | B22: 48.96 | C22: 4.36 | D22: Chalons-en-Champagne | E22: France | F22: 2 | G22: FALSE | H22: 1
A23: 22 | B23: 50.29 | C23: 2.77 | D23: Arras | E23: France | F23: 2 | G23: FALSE | H23: 1
A24: 23 | B24: 48.77 | C24: 5.16 | D24: Bar-le-Duc | E24: France | F24: 2 | G24: FALSE | H24: 1
A25: 24 | B25: 48.58 | C25: 7.75 | D25: Strasbourg | E25: France | F25: 2 | G25: TRUE | H25: 1
A26: 25 | B26: 48.39 | C26: -4.49 | D26: Brest | E26: France | F26: 2 | G26: FALSE | H26: 1
A27: 26 | B27: 47.75 | C27: -3.37 | D27: Lorient | E27: France | F27: 2 | G27: FALSE | H27: 1
A28: 27 | B28: 45.83 | C28: 1.26 | D28: Limoges | E28: France | F28: 2 | G28: FALSE | H28: 1
A29: 28 | B29: 46.58 | C29: -0.34 | D29: Poitiers | E29: France | F29: 2 | G29: FALSE | H29: 1
A30: 29 | B30: 43.49 | C30: -1.47 | D30: Bayonne | E30: France | F30: 2 | G30: TRUE | H30: 1
A31: 30 | B31: 44.2 | C31: 0.62 | D31: Agen | E31: France | F31: 2 | G31: FALSE | H31: 1
A32: 31 | B32: 45.19 | C32: 5.72 | D32: Grenoble | E32: France | F32: 2 | G32: TRUE | H32: 1
A33: 32 | B33: 47.39 | C33: 0.69 | D33: Tours | E33: France | F33: 2 | G33: FALSE | H33: 1
A34: 33 | B34: 44.85 | C34: -0.57 | D34: Bordeaux | E34: France | F34: 2 | G34: TRUE | H34: 1
A35: 34 | B35: 45.73 | C35: 4.83 | D35: Lyon | E35: France | F35: 2 | G35: TRUE | H35: 1
A36: 35 | B36: 43.3 | C36: 5.37 | D36: Marseille | E36: France | F36: 2 | G36: TRUE | H36: 1
A37: 36 | B37: 45.47 | C37: 9.17 | D37: Milan | E37: Italy | F37: 3 | G37: TRUE | H37: 1
A38: 37 | B38: 45.079167 | C38: 7.676111 | D38: Turin | E38: Italy | F38: 3 | G38: TRUE | H38: 1
A39: 38 | B39: 44.407186 | C39: 8.933983 | D39: Genoa | E39: Italy | F39: 3 | G39: FALSE | H39: 1
A40: 39 | B40: 44.493889 | C40: 11.342778 | D40: Bologna | E40: Italy | F40: 3 | G40: FALSE | H40: 1
...

Sheet Edges
A1: Edge_ID | B1: Source | C1: Src_Name | D1: Destination | E1: Dst_Name | F1: Computed Length (km) | G1: Availability | H1: Capacity | I1: src LA | J1: src LONG | K1: dst LA | L1: dst LONG
A2: 1 | B2: =_xlfn.XLOOKUP(C2,Nodes!$D:$D,Nodes!$A:$A) -> 2 | C2: Frankfurt | D2: =_xlfn.XLOOKUP(E2,Nodes!$D:$D,Nodes!$A:$A) -> 1 | E2: Hannover | F2: =6371*2*ASIN(SQRT(SIN(RADIANS((K2-I2)/2))^2+COS(RADIANS(I2))*COS(RADIANS(K2))*SIN(RADIANS((L2-J2)/2))^2)) -> 266.49892 | G2: =(0.9999)^F2 -> 0.97370079 | H2: N/A | I2: =_xlfn.XLOOKUP(B2,Nodes!$A:$A,Nodes!$B:$B) -> 50.1 | J2: =_xlfn.XLOOKUP(B2,Nodes!$A:$A,Nodes!$C:$C) -> 8.67 | K2: =_xlfn.XLOOKUP(D2,Nodes!$A:$A,Nodes!$B:$B) -> 52.39 | L2: =_xlfn.XLOOKUP(D2,Nodes!$A:$A,Nodes!$C:$C) -> 9.8
A3: 2 | B3: =_xlfn.XLOOKUP(C3,Nodes!$D:$D,Nodes!$A:$A) -> 3 | C3: Hamburg | D3: =_xlfn.XLOOKUP(E3,Nodes!$D:$D,Nodes!$A:$A) -> 1 | E3: Hannover | F3: =6371*2*ASIN(SQRT(SIN(RADIANS((K3-I3)/2))^2+COS(RADIANS(I3))*COS(RADIANS(K3))*SIN(RADIANS((L3-J3)/2))^2)) -> 129.82455 | G3: =(0.9999)^F3 -> 0.98710081 | H3: N/A | I3: =_xlfn.XLOOKUP(B3,Nodes!$A:$A,Nodes!$B:$B) -> 53.55 | J3: =_xlfn.XLOOKUP(B3,Nodes!$A:$A,Nodes!$C:$C) -> 10.02 | K3: =_xlfn.XLOOKUP(D3,Nodes!$A:$A,Nodes!$B:$B) -> 52.39 | L3: =_xlfn.XLOOKUP(D3,Nodes!$A:$A,Nodes!$C:$C) -> 9.8
A4: 3 | B4: =_xlfn.XLOOKUP(C4,Nodes!$D:$D,Nodes!$A:$A) -> 5 | C4: Bremen | D4: =_xlfn.XLOOKUP(E4,Nodes!$D:$D,Nodes!$A:$A) -> 1 | E4: Hannover | F4: =6371*2*ASIN(SQRT(SIN(RADIANS((K4-I4)/2))^2+COS(RADIANS(I4))*COS(RADIANS(K4))*SIN(RADIANS((L4-J4)/2))^2)) -> 102.07548 | G4: =(0.9999)^F4 -> 0.98984387 | H4: N/A | I4: =_xlfn.XLOOKUP(B4,Nodes!$A:$A,Nodes!$B:$B) -> 53.08 | J4: =_xlfn.XLOOKUP(B4,Nodes!$A:$A,Nodes!$C:$C) -> 8.8 | K4: =_xlfn.XLOOKUP(D4,Nodes!$A:$A,Nodes!$B:$B) -> 52.39 | L4: =_xlfn.XLOOKUP(D4,Nodes!$A:$A,Nodes!$C:$C) -> 9.8
A5: 4 | B5: =_xlfn.XLOOKUP(C5,Nodes!$D:$D,Nodes!$A:$A) -> 6 | C5: Berlin | D5: =_xlfn.XLOOKUP(E5,Nodes!$D:$D,Nodes!$A:$A) -> 1 | E5: Hannover | F5: =6371*2*ASIN(SQRT(SIN(RADIANS((K5-I5)/2))^2+COS(RADIANS(I5))*COS(RADIANS(K5))*SIN(RADIANS((L5-J5)/2))^2)) -> 244.34003 | G5: =(0.9999)^F5 -> 0.9758609 | H5: N/A | I5: =_xlfn.XLOOKUP(B5,Nodes!$A:$A,Nodes!$B:$B) -> 52.52 | J5: =_xlfn.XLOOKUP(B5,Nodes!$A:$A,Nodes!$C:$C) -> 13.4 | K5: =_xlfn.XLOOKUP(D5,Nodes!$A:$A,Nodes!$B:$B) -> 52.39 | L5: =_xlfn.XLOOKUP(D5,Nodes!$A:$A,Nodes!$C:$C) -> 9.8
A6: 5 | B6: =_xlfn.XLOOKUP(C6,Nodes!$D:$D,Nodes!$A:$A) -> 14 | C6: Dortmund | D6: =_xlfn.XLOOKUP(E6,Nodes!$D:$D,Nodes!$A:$A) -> 1 | E6: Hannover | F6: =6371*2*ASIN(SQRT(SIN(RADIANS((K6-I6)/2))^2+COS(RADIANS(I6))*COS(RADIANS(K6))*SIN(RADIANS((L6-J6)/2))^2)) -> 186.68459 | G6: =(0.9999)^F6 -> 0.9815038 | H6: N/A | I6: =_xlfn.XLOOKUP(B6,Nodes!$A:$A,Nodes!$B:$B) -> 51.51 | J6: =_xlfn.XLOOKUP(B6,Nodes!$A:$A,Nodes!$C:$C) -> 7.48 | K6: =_xlfn.XLOOKUP(D6,Nodes!$A:$A,Nodes!$B:$B) -> 52.39 | L6: =_xlfn.XLOOKUP(D6,Nodes!$A:$A,Nodes!$C:$C) -> 9.8
A7: 6 | B7: =_xlfn.XLOOKUP(C7,Nodes!$D:$D,Nodes!$A:$A) -> 15 | C7: Dusseldorf | D7: =_xlfn.XLOOKUP(E7,Nodes!$D:$D,Nodes!$A:$A) -> 2 | E7: Frankfurt | F7: =6371*2*ASIN(SQRT(SIN(RADIANS((K7-I7)/2))^2+COS(RADIANS(I7))*COS(RADIANS(K7))*SIN(RADIANS((L7-J7)/2))^2)) -> 183.10841 | G7: =(0.9999)^F7 -> 0.98185488 | H7: N/A | I7: =_xlfn.XLOOKUP(B7,Nodes!$A:$A,Nodes!$B:$B) -> 51.23 | J7: =_xlfn.XLOOKUP(B7,Nodes!$A:$A,Nodes!$C:$C) -> 6.78 | K7: =_xlfn.XLOOKUP(D7,Nodes!$A:$A,Nodes!$B:$B) -> 50.1 | L7: =_xlfn.XLOOKUP(D7,Nodes!$A:$A,Nodes!$C:$C) -> 8.67
A8: 7 | B8: =_xlfn.XLOOKUP(C8,Nodes!$D:$D,Nodes!$A:$A) -> 2 | C8: Frankfurt | D8: =_xlfn.XLOOKUP(E8,Nodes!$D:$D,Nodes!$A:$A) -> 3 | E8: Hamburg | F8: =6371*2*ASIN(SQRT(SIN(RADIANS((K8-I8)/2))^2+COS(RADIANS(I8))*COS(RADIANS(K8))*SIN(RADIANS((L8-J8)/2))^2)) -> 394.66293 | G8: =(0.9999)^F8 -> 0.96130046 | H8: N/A | I8: =_xlfn.XLOOKUP(B8,Nodes!$A:$A,Nodes!$B:$B) -> 50.1 | J8: =_xlfn.XLOOKUP(B8,Nodes!$A:$A,Nodes!$C:$C) -> 8.67 | K8: =_xlfn.XLOOKUP(D8,Nodes!$A:$A,Nodes!$B:$B) -> 53.55 | L8: =_xlfn.XLOOKUP(D8,Nodes!$A:$A,Nodes!$C:$C) -> 10.02
A9: 8 | B9: =_xlfn.XLOOKUP(C9,Nodes!$D:$D,Nodes!$A:$A) -> 5 | C9: Bremen | D9: =_xlfn.XLOOKUP(E9,Nodes!$D:$D,Nodes!$A:$A) -> 3 | E9: Hamburg | F9: =6371*2*ASIN(SQRT(SIN(RADIANS((K9-I9)/2))^2+COS(RADIANS(I9))*COS(RADIANS(K9))*SIN(RADIANS((L9-J9)/2))^2)) -> 96.431414 | G9: =(0.9999)^F9 -> 0.99040273 | H9: N/A | I9: =_xlfn.XLOOKUP(B9,Nodes!$A:$A,Nodes!$B:$B) -> 53.08 | J9: =_xlfn.XLOOKUP(B9,Nodes!$A:$A,Nodes!$C:$C) -> 8.8 | K9: =_xlfn.XLOOKUP(D9,Nodes!$A:$A,Nodes!$B:$B) -> 53.55 | L9: =_xlfn.XLOOKUP(D9,Nodes!$A:$A,Nodes!$C:$C) -> 10.02
A10: 9 | B10: =_xlfn.XLOOKUP(C10,Nodes!$D:$D,Nodes!$A:$A) -> 6 | C10: Berlin | D10: =_xlfn.XLOOKUP(E10,Nodes!$D:$D,Nodes!$A:$A) -> 3 | E10: Hamburg | F10: =6371*2*ASIN(SQRT(SIN(RADIANS((K10-I10)/2))^2+COS(RADIANS(I10))*COS(RADIANS(K10))*SIN(RADIANS((L10-J10)/2))^2)) -> 253.33005 | G10: =(0.9999)^F10 -> 0.97498395 | H10: N/A | I10: =_xlfn.XLOOKUP(B10,Nodes!$A:$A,Nodes!$B:$B) -> 52.52 | J10: =_xlfn.XLOOKUP(B10,Nodes!$A:$A,Nodes!$C:$C) -> 13.4 | K10: =_xlfn.XLOOKUP(D10,Nodes!$A:$A,Nodes!$B:$B) -> 53.55 | L10: =_xlfn.XLOOKUP(D10,Nodes!$A:$A,Nodes!$C:$C) -> 10.02
A11: 10 | B11: =_xlfn.XLOOKUP(C11,Nodes!$D:$D,Nodes!$A:$A) -> 5 | C11: Bremen | D11: =_xlfn.XLOOKUP(E11,Nodes!$D:$D,Nodes!$A:$A) -> 4 | E11: Norden | F11: =6371*2*ASIN(SQRT(SIN(RADIANS((K11-I11)/2))^2+COS(RADIANS(I11))*COS(RADIANS(K11))*SIN(RADIANS((L11-J11)/2))^2)) -> 120.35574 | G11: =(0.9999)^F11 -> 0.98803597 | H11: N/A | I11: =_xlfn.XLOOKUP(B11,Nodes!$A:$A,Nodes!$B:$B) -> 53.08 | J11: =_xlfn.XLOOKUP(B11,Nodes!$A:$A,Nodes!$C:$C) -> 8.8 | K11: =_xlfn.XLOOKUP(D11,Nodes!$A:$A,Nodes!$B:$B) -> 53.6 | L11: =_xlfn.XLOOKUP(D11,Nodes!$A:$A,Nodes!$C:$C) -> 7.21
A12: 11 | B12: =_xlfn.XLOOKUP(C12,Nodes!$D:$D,Nodes!$A:$A) -> 14 | C12: Dortmund | D12: =_xlfn.XLOOKUP(E12,Nodes!$D:$D,Nodes!$A:$A) -> 4 | E12: Norden | F12: =6371*2*ASIN(SQRT(SIN(RADIANS((K12-I12)/2))^2+COS(RADIANS(I12))*COS(RADIANS(K12))*SIN(RADIANS((L12-J12)/2))^2)) -> 233.11268 | G12: =(0.9999)^F12 -> 0.9769572 | H12: N/A | I12: =_xlfn.XLOOKUP(B12,Nodes!$A:$A,Nodes!$B:$B) -> 51.51 | J12: =_xlfn.XLOOKUP(B12,Nodes!$A:$A,Nodes!$C:$C) -> 7.48 | K12: =_xlfn.XLOOKUP(D12,Nodes!$A:$A,Nodes!$B:$B) -> 53.6 | L12: =_xlfn.XLOOKUP(D12,Nodes!$A:$A,Nodes!$C:$C) -> 7.21
A13: 12 | B13: =_xlfn.XLOOKUP(C13,Nodes!$D:$D,Nodes!$A:$A) -> 2 | C13: Frankfurt | D13: =_xlfn.XLOOKUP(E13,Nodes!$D:$D,Nodes!$A:$A) -> 7 | E13: Munich | F13: =6371*2*ASIN(SQRT(SIN(RADIANS((K13-I13)/2))^2+COS(RADIANS(I13))*COS(RADIANS(K13))*SIN(RADIANS((L13-J13)/2))^2)) -> 304.14914 | G13: =(0.9999)^F13 -> 0.97004149 | H13: N/A | I13: =_xlfn.XLOOKUP(B13,Nodes!$A:$A,Nodes!$B:$B) -> 50.1 | J13: =_xlfn.XLOOKUP(B13,Nodes!$A:$A,Nodes!$C:$C) -> 8.67 | K13: =_xlfn.XLOOKUP(D13,Nodes!$A:$A,Nodes!$B:$B) -> 48.13 | L13: =_xlfn.XLOOKUP(D13,Nodes!$A:$A,Nodes!$C:$C) -> 11.57
... A123: 122 | B123: =_xlfn.XLOOKUP(C123,Nodes!$D:$D,Nodes!$A:$A) -> 7 | C123: Munich | D123: =_xlfn.XLOOKUP(E123,Nodes!$D:$D,Nodes!$A:$A) -> 61 | E123: Zurich (ETH) | F123: =6371*2*ASIN(SQRT(SIN(RADIANS((K123-I123)/2))^2+COS(RADIANS(I123))*COS(RADIANS(K123))*SIN(RADIANS((L123-J123)/2))^2)) -> 241.40776 | G123: =(0.9999)^F123 -> 0.9761471 | H123: N/A | I123: =_xlfn.XLOOKUP(B123,Nodes!$A:$A,Nodes!$B:$B) -> 48.13 | J123: =_xlfn.XLOOKUP(B123,Nodes!$A:$A,Nodes!$C:$C) -> 11.57 | K123: =_xlfn.XLOOKUP(D123,Nodes!$A:$A,Nodes!$B:$B) -> 47.377 | L123: =_xlfn.XLOOKUP(D123,Nodes!$A:$A,Nodes!$C:$C) -> 8.541
