Workbook

Sheet Nodes
A1: Node_ID | B1: Latitude | C1: Longitude | D1: Location Name | E1: Country | F1: Domain | G1: Border | H1: node_prob
A2: 1 | B2: 52.39 | C2: 9.8 | D2: Hannover | E2: Germany | F2: 1 | G2: FALSE | H2: 1
A3: 2 | B3: 50.1 | C3: 8.67 | D3: Frankfurt | E3: Germany | F3: 1 | G3: TRUE | H3: 1
A4: 3 | B4: 53.55 | C4: 10.02 | D4: Hamburg | E4: Germany | F4: 1 | G4: TRUE | H4: 1
A5: 4 | B5: 53.6 | C5: 7.21 | D5: Norden | E5: Germany | F5: 1 | G5: FALSE | H5: 1
A6: 5 | B6: 53.08 | C6: 8.8 | D6: Bremen | E6: Germany | F6: 1 | G6: FALSE | H6: 1
A7: 6 | B7: 52.52 | C7: 13.4 | D7: Berlin | E7: Germany | F7: 1 | G7: FALSE | H7: 1
A8: 7 | B8: 48.13 | C8: 11.57 | D8: Munich | E8: Germany | F8: 1 | G8: TRUE | H8: 1
A9: 8 | B9: 48.4 | C9: 9.99 | D9: Ulm | E9: Germany | F9: 1 | G9: FALSE | H9: 1
A10: 9 | B10: 49.45 | C10: 11.08 | D10: Nuernberg | E10: Germany | F10: 1 | G10: FALSE | H10: 1
A11: 10 | B11: 48.73 | C11: 9.12 | D11: Stuttgart | E11: Germany | F11: 1 | G11: FALSE | H11: 1
A12: 11 | B12: 49.01 | C12: 8.41 | D12: Karlsruhe | E12: Germany | F12: 1 | G12: FALSE | H12: 1
A13: 12 | B13: 49.49 | C13: 8.49 | D13: Mannheim | E13: Germany | F13: 1 | G13: FALSE | H13: 1
... A18: 17 | B18: 51.34 | C18: 12.38 | D18: Leipzig | E18: Germany | F18: 1 | G18: FALSE | H18: 1
A19: 18 | B19: 50.95 | C19: 1.86 | D19: Calais | E19: France | F19: 2 | G19: FALSE | H19: 1
A20: 19 | B20: 47.9 | C20: 1.91 | D20: Orleans | E20: France | F20: 2 | G20: FALSE | H20: 1
A21: 20 | B21: 48.85 | C21: 2.35 | D21: Paris | E21: France | F21: 2 | G21: TRUE | H21: 1
A22: 21 | B22: 48.96 | C22: 4.36 | D22: Chalons-en-Champagne | E22: France | F22: 2 | G22: FALSE | H22: 1
A23: 22 | B23: 50.29 | C23: 2.77 | D23: Arras | E23: France | F23: 2 | G23: FALSE | H23: 1
A24: 23 | B24: 48.77 | C24: 5.16 | D24: Bar-le-Duc | E24: France | F24: 2 | G24: FALSE | H24: 1
A25: 24 | B25: 48.58 | C25: 7.75 | D25: Strasbourg | E25: France | F25: 2 | G25: TRUE | H25: 1
A26: 25 | B26: 48.39 | C26: -4.49 | D26: Brest | E26: France | F26: 2 | G26: FALSE | H26: 1
A27: 26 | B27: 47.75 | C27: -3.37 | D27: Lorient | E27: France | F27: 2 | G27: FALSE | H27: 1
A28: 27 | B28: 45.83 | C28: 1.26 | D28: Limoges | E28: France | F28: 2 | G28: FALSE | H28: 1
A29: 28 | B29: 46.58 | C29: -0.34 | D29: Poitiers | E29: France | F29: 2 | G29: FALSE | H29: 1
A30: 29 | B30: 43.49 | C30: -1.47 | D30: Bayonne | E30: France | F30: 2 | G30: FALSE | H30: 1
A31: 30 | B31: 44.2 | C31: 0.62 | D31: Agen | E31: France | F31: 2 | G31: FALSE | H31: 1
A32: 31 | B32: 45.19 | C32: 5.72 | D32: Grenoble | E32: France | F32: 2 | G32: FALSE | H32: 1
A33: 32 | B33: 47.39 | C33: 0.69 | D33: Tours | E33: France | F33: 2 | G33: FALSE | H33: 1
A34: 33 | B34: 44.85 | C34: -0.57 | D34: Bordeaux | E34: France | F34: 2 | G34: TRUE | H34: 1
A35: 34 | B35: 45.73 | C35: 4.83 | D35: Lyon | E35: France | F35: 2 | G35: TRUE | H35: 1
A36: 35 | B36: 43.3 | C36: 5.37 | D36: Marseille | E36: France | F36: 2 | G36: TRUE | H36: 1
A37: 36 | B37: 45.47 | C37: 9.17 | D37: Milan | E37: Italy | F37: 3 | G37: TRUE | H37: 1
A38: 37 | B38: 45.079167 | C38: 7.676111 | D38: Turin | E38: Italy | F38: 3 | G38: FALSE | H38: 1
A39: 38 | B39: 44.407186 | C39: 8.933983 | D39: Genoa | E39: Italy | F39: 3 | G39: FALSE | H39: 1
A40: 39 | B40: 44.493889 | C40: 11.342778 | D40: Bologna | E40: Italy | F40: 3 | G40: FALSE | H40: 1
A41: 40 | B41: 43.771389 | C41: 11.254167 | D41: Florence | E41: Italy | F41: 3 | G41: FALSE | H41: 1
A42: 41 | B42: 41.88 | C42: 12.5 | D42: Rome | E42: Italy | F42: 3 | G42: TRUE | H42: 1
A43: 42 | B43: 40.833333 | C43: 14.25 | D43: Naples | E43: Italy | F43: 3 | G43: FALSE | H43: 1
A44: 43 | B44: 38.12 | C44: 13.35 | D44: Palermo | E44: Italy | F44: 3 | G44: FALSE | H44: 1
...

Sheet Edges
A1: Edge_ID | B1: Source | C1: Location Name | D1: Destination | E1: Dst Name | F1: Computed Length (km) | G1: Availability | H1: Capacity
A2: 1 | B2: {=INDEX(Nodes!$A:$A,MATCH(C2,Nodes!$D:$D,0))} -> 2 | C2: Frankfurt | D2: {=INDEX(Nodes!$A:$A,MATCH(E2,Nodes!$D:$D,0))} -> 1 | E2: Hannover | F2: 266.49892 | G2: 0.97370079 | H2: N/A | I2: =_xlfn.XLOOKUP(C2,Nodes!$D:$D,Nodes!$E:$E) -> Germany | J2: =_xlfn.XLOOKUP(E2,Nodes!$D:$D,Nodes!$E:$E) -> Germany
A3: 2 | B3: {=INDEX(Nodes!$A:$A,MATCH(C3,Nodes!$D:$D,0))} -> 3 | C3: Hamburg | D3: {=INDEX(Nodes!$A:$A,MATCH(E3,Nodes!$D:$D,0))} -> 1 | E3: Hannover | F3: 129.82455 | G3: 0.98710081 | H3: N/A | I3: =_xlfn.XLOOKUP(C3,Nodes!$D:$D,Nodes!$E:$E) -> Germany | J3: =_xlfn.XLOOKUP(E3,Nodes!$D:$D,Nodes!$E:$E) -> Germany
A4: 3 | B4: {=INDEX(Nodes!$A:$A,MATCH(C4,Nodes!$D:$D,0))} -> 5 | C4: Bremen | D4: {=INDEX(Nodes!$A:$A,MATCH(E4,Nodes!$D:$D,0))} -> 1 | E4: Hannover | F4: 102.07548 | G4: 0.98984387 | H4: N/A | I4: =_xlfn.XLOOKUP(C4,Nodes!$D:$D,Nodes!$E:$E) -> Germany | J4: =_xlfn.XLOOKUP(E4,Nodes!$D:$D,Nodes!$E:$E) -> Germany
A5: 4 | B5: {=INDEX(Nodes!$A:$A,MATCH(C5,Nodes!$D:$D,0))} -> 6 | C5: Berlin | D5: {=INDEX(Nodes!$A:$A,MATCH(E5,Nodes!$D:$D,0))} -> 1 | E5: Hannover | F5: 244.34003 | G5: 0.9758609 | H5: N/A | I5: =_xlfn.XLOOKUP(C5,Nodes!$D:$D,Nodes!$E:$E) -> Germany | J5: =_xlfn.XLOOKUP(E5,Nodes!$D:$D,Nodes!$E:$E) -> Germany
A6: 5 | B6: {=INDEX(Nodes!$A:$A,MATCH(C6,Nodes!$D:$D,0))} -> 14 | C6: Dortmund | D6: {=INDEX(Nodes!$A:$A,MATCH(E6,Nodes!$D:$D,0))} -> 1 | E6: Hannover | F6: 186.68459 | G6: 0.9815038 | H6: N/A | I6: =_xlfn.XLOOKUP(C6,Nodes!$D:$D,Nodes!$E:$E) -> Germany | J6: =_xlfn.XLOOKUP(E6,Nodes!$D:$D,Nodes!$E:$E) -> Germany
A7: 6 | B7: {=INDEX(Nodes!$A:$A,MATCH(C7,Nodes!$D:$D,0))} -> 15 | C7: Dusseldorf | D7: {=INDEX(Nodes!$A:$A,MATCH(E7,Nodes!$D:$D,0))} -> 2 | E7: Frankfurt | F7: 274.66262 | G7: 0.97290617 | H7: N/A | I7: =_xlfn.XLOOKUP(C7,Nodes!$D:$D,Nodes!$E:$E) -> Germany | J7: =_xlfn.XLOOKUP(E7,Nodes!$D:$D,Nodes!$E:$E) -> Germany
A8: 7 | B8: {=INDEX(Nodes!$A:$A,MATCH(C8,Nodes!$D:$D,0))} -> 2 | C8: Frankfurt | D8: {=INDEX(Nodes!$A:$A,MATCH(E8,Nodes!$D:$D,0))} -> 3 | E8: Hamburg | F8: 591.9944 | G8: 0.94251598 | H8: N/A | I8: =_xlfn.XLOOKUP(C8,Nodes!$D:$D,Nodes!$E:$E) -> Germany | J8: =_xlfn.XLOOKUP(E8,Nodes!$D:$D,Nodes!$E:$E) -> Germany
A9: 8 | B9: {=INDEX(Nodes!$A:$A,MATCH(C9,Nodes!$D:$D,0))} -> 5 | C9: Bremen | D9: {=INDEX(Nodes!$A:$A,MATCH(E9,Nodes!$D:$D,0))} -> 3 | E9: Hamburg | F9: 96.431414 | G9: 0.99040273 | H9: N/A | I9: =_xlfn.XLOOKUP(C9,Nodes!$D:$D,Nodes!$E:$E) -> Germany | J9: =_xlfn.XLOOKUP(E9,Nodes!$D:$D,Nodes!$E:$E) -> Germany
A10: 9 | B10: {=INDEX(Nodes!$A:$A,MATCH(C10,Nodes!$D:$D,0))} -> 6 | C10: Berlin | D10: {=INDEX(Nodes!$A:$A,MATCH(E10,Nodes!$D:$D,0))} -> 3 | E10: Hamburg | F10: 379.99508 | G10: 0.96271159 | H10: N/A | I10: =_xlfn.XLOOKUP(C10,Nodes!$D:$D,Nodes!$E:$E) -> Germany | J10: =_xlfn.XLOOKUP(E10,Nodes!$D:$D,Nodes!$E:$E) -> Germany
A11: 10 | B11: {=INDEX(Nodes!$A:$A,MATCH(C11,Nodes!$D:$D,0))} -> 5 | C11: Bremen | D11: {=INDEX(Nodes!$A:$A,MATCH(E11,Nodes!$D:$D,0))} -> 4 | E11: Norden | F11: 120.35574 | G11: 0.98803597 | H11: N/A | I11: =_xlfn.XLOOKUP(C11,Nodes!$D:$D,Nodes!$E:$E) -> Germany | J11: =_xlfn.XLOOKUP(E11,Nodes!$D:$D,Nodes!$E:$E) -> Germany
A12: 11 | B12: {=INDEX(Nodes!$A:$A,MATCH(C12,Nodes!$D:$D,0))} -> 14 | C12: Dortmund | D12: {=INDEX(Nodes!$A:$A,MATCH(E12,Nodes!$D:$D,0))} -> 4 | E12: Norden | F12: 233.11268 | G12: 0.9769572 | H12: N/A | I12: =_xlfn.XLOOKUP(C12,Nodes!$D:$D,Nodes!$E:$E) -> Germany | J12: =_xlfn.XLOOKUP(E12,Nodes!$D:$D,Nodes!$E:$E) -> Germany
A13: 12 | B13: {=INDEX(Nodes!$A:$A,MATCH(C13,Nodes!$D:$D,0))} -> 2 | C13: Frankfurt | D13: {=INDEX(Nodes!$A:$A,MATCH(E13,Nodes!$D:$D,0))} -> 7 | E13: Munich | F13: 456.22371 | G13: 0.9554005 | H13: N/A | I13: =_xlfn.XLOOKUP(C13,Nodes!$D:$D,Nodes!$E:$E) -> Germany | J13: =_xlfn.XLOOKUP(E13,Nodes!$D:$D,Nodes!$E:$E) -> Germany
... A31: 30 | B31: {=INDEX(Nodes!$A:$A,MATCH(C31,Nodes!$D:$D,0))} -> 6 | C31: Berlin | D31: {=INDEX(Nodes!$A:$A,MATCH(E31,Nodes!$D:$D,0))} -> 17 | E31: Leipzig | F31: 148.68126 | G31: 0.98524113 | H31: N/A | I31: =_xlfn.XLOOKUP(C31,Nodes!$D:$D,Nodes!$E:$E) -> Germany | J31: =_xlfn.XLOOKUP(E31,Nodes!$D:$D,Nodes!$E:$E) -> Germany
A32: 31 | B32: {=INDEX(Nodes!$A:$A,MATCH(C32,Nodes!$D:$D,0))} -> 18 | C32: Calais | D32: {=INDEX(Nodes!$A:$A,MATCH(E32,Nodes!$D:$D,0))} -> 22 | E32: Arras | F32: 97.504665 | G32: =(0.9999)^F32 -> 0.99029643 | H32: N/A | I32: =_xlfn.XLOOKUP(C32,Nodes!$D:$D,Nodes!$E:$E) -> France | J32: =_xlfn.XLOOKUP(E32,Nodes!$D:$D,Nodes!$E:$E) -> France
A33: 32 | B33: {=INDEX(Nodes!$A:$A,MATCH(C33,Nodes!$D:$D,0))} -> 18 | C33: Calais | D33: {=INDEX(Nodes!$A:$A,MATCH(E33,Nodes!$D:$D,0))} -> 24 | E33: Strasbourg | F33: 498.18463 | G33: =(0.9999)^F33 -> 0.95139975 | H33: N/A | I33: =_xlfn.XLOOKUP(C33,Nodes!$D:$D,Nodes!$E:$E) -> France | J33: =_xlfn.XLOOKUP(E33,Nodes!$D:$D,Nodes!$E:$E) -> France
A34: 33 | B34: {=INDEX(Nodes!$A:$A,MATCH(C34,Nodes!$D:$D,0))} -> 20 | C34: Paris | D34: {=INDEX(Nodes!$A:$A,MATCH(E34,Nodes!$D:$D,0))} -> 19 | E34: Orleans | F34: 110.52086 | G34: =(0.9999)^F34 -> 0.98900822 | H34: N/A | I34: =_xlfn.XLOOKUP(C34,Nodes!$D:$D,Nodes!$E:$E) -> France | J34: =_xlfn.XLOOKUP(E34,Nodes!$D:$D,Nodes!$E:$E) -> France
A35: 34 | B35: {=INDEX(Nodes!$A:$A,MATCH(C35,Nodes!$D:$D,0))} -> 21 | C35: Chalons-en-Champagne | D35: {=INDEX(Nodes!$A:$A,MATCH(E35,Nodes!$D:$D,0))} -> 19 | E35: Orleans | F35: 215.78066 | G35: =(0.9999)^F35 -> 0.97865202 | H35: N/A | I35: =_xlfn.XLOOKUP(C35,Nodes!$D:$D,Nodes!$E:$E) -> France | J35: =_xlfn.XLOOKUP(E35,Nodes!$D:$D,Nodes!$E:$E) -> France
A36: 35 | B36: {=INDEX(Nodes!$A:$A,MATCH(C36,Nodes!$D:$D,0))} -> 21 | C36: Chalons-en-Champagne | D36: {=INDEX(Nodes!$A:$A,MATCH(E36,Nodes!$D:$D,0))} -> 20 | E36: Paris | F36: 147.41378 | G36: =(0.9999)^F36 -> 0.98536602 | H36: N/A | I36: =_xlfn.XLOOKUP(C36,Nodes!$D:$D,Nodes!$E:$E) -> France | J36: =_xlfn.XLOOKUP(E36,Nodes!$D:$D,Nodes!$E:$E) -> France
A37: 36 | B37: {=INDEX(Nodes!$A:$A,MATCH(C37,Nodes!$D:$D,0))} -> 21 | C37: Chalons-en-Champagne | D37: {=INDEX(Nodes!$A:$A,MATCH(E37,Nodes!$D:$D,0))} -> 22 | E37: Arras | F37: 187.04159 | G37: =(0.9999)^F37 -> 0.98146876 | H37: N/A | I37: =_xlfn.XLOOKUP(C37,Nodes!$D:$D,Nodes!$E:$E) -> France | J37: =_xlfn.XLOOKUP(E37,Nodes!$D:$D,Nodes!$E:$E) -> France
A38: 37 | B38: {=INDEX(Nodes!$A:$A,MATCH(C38,Nodes!$D:$D,0))} -> 21 | C38: Chalons-en-Champagne | D38: {=INDEX(Nodes!$A:$A,MATCH(E38,Nodes!$D:$D,0))} -> 23 | E38: Bar-le-Duc | F38: 62.214986 | G38: =(0.9999)^F38 -> 0.99379751 | H38: N/A | I38: =_xlfn.XLOOKUP(C38,Nodes!$D:$D,Nodes!$E:$E) -> France | J38: =_xlfn.XLOOKUP(E38,Nodes!$D:$D,Nodes!$E:$E) -> France
A39: 38 | B39: {=INDEX(Nodes!$A:$A,MATCH(C39,Nodes!$D:$D,0))} -> 23 | C39: Bar-le-Duc | D39: {=INDEX(Nodes!$A:$A,MATCH(E39,Nodes!$D:$D,0))} -> 22 | E39: Arras | F39: 241.46937 | G39: =(0.9999)^F39 -> 0.97614109 | H39: N/A | I39: =_xlfn.XLOOKUP(C39,Nodes!$D:$D,Nodes!$E:$E) -> France | J39: =_xlfn.XLOOKUP(E39,Nodes!$D:$D,Nodes!$E:$E) -> France
A40: 39 | B40: {=INDEX(Nodes!$A:$A,MATCH(C40,Nodes!$D:$D,0))} -> 23 | C40: Bar-le-Duc | D40: {=INDEX(Nodes!$A:$A,MATCH(E40,Nodes!$D:$D,0))} -> 24 | E40: Strasbourg | F40: 191.33193 | G40: =(0.9999)^F40 -> 0.98104775 | H40: N/A | I40: =_xlfn.XLOOKUP(C40,Nodes!$D:$D,Nodes!$E:$E) -> France | J40: =_xlfn.XLOOKUP(E40,Nodes!$D:$D,Nodes!$E:$E) -> France
A41: 40 | B41: {=INDEX(Nodes!$A:$A,MATCH(C41,Nodes!$D:$D,0))} -> 26 | C41: Lorient | D41: {=INDEX(Nodes!$A:$A,MATCH(E41,Nodes!$D:$D,0))} -> 25 | E41: Brest | F41: 109.49615 | G41: =(0.9999)^F41 -> 0.98910957 | H41: N/A | I41: =_xlfn.XLOOKUP(C41,Nodes!$D:$D,Nodes!$E:$E) -> France | J41: =_xlfn.XLOOKUP(E41,Nodes!$D:$D,Nodes!$E:$E) -> France
A42: 41 | B42: {=INDEX(Nodes!$A:$A,MATCH(C42,Nodes!$D:$D,0))} -> 27 | C42: Limoges | D42: {=INDEX(Nodes!$A:$A,MATCH(E42,Nodes!$D:$D,0))} -> 28 | E42: Poitiers | F42: 148.70881 | G42: =(0.9999)^F42 -> 0.98523841 | H42: N/A | I42: =_xlfn.XLOOKUP(C42,Nodes!$D:$D,Nodes!$E:$E) -> France | J42: =_xlfn.XLOOKUP(E42,Nodes!$D:$D,Nodes!$E:$E) -> France
A43: 42 | B43: {=INDEX(Nodes!$A:$A,MATCH(C43,Nodes!$D:$D,0))} -> 27 | C43: Limoges | D43: {=INDEX(Nodes!$A:$A,MATCH(E43,Nodes!$D:$D,0))} -> 29 | E43: Bayonne | F43: 338.07396 | G43: =(0.9999)^F43 -> 0.96675605 | H43: N/A | I43: =_xlfn.XLOOKUP(C43,Nodes!$D:$D,Nodes!$E:$E) -> France | J43: =_xlfn.XLOOKUP(E43,Nodes!$D:$D,Nodes!$E:$E) -> France
... A155: 154 | B155: {=INDEX(Nodes!$A:$A,MATCH(C155,Nodes!$D:$D,0))} -> 24 | C155: Strasbourg | D155: {=INDEX(Nodes!$A:$A,MATCH(E155,Nodes!$D:$D,0))} -> 62 | E155: Zurich (ETH) | F155: 218.27284 | G155: =(0.9999)^F155 -> 0.97840814 | H155: N/A | I155: =_xlfn.XLOOKUP(C155,Nodes!$D:$D,Nodes!$E:$E) -> France | J155: =_xlfn.XLOOKUP(E155,Nodes!$D:$D,Nodes!$E:$E) -> Switzerland
